2025-08-10 09:18:55,655 ERROR: Exception on / [GET] [in E:\Nata\Git-nata\ReadMaster\venv\Lib\site-packages\flask\app.py:875]
Traceback (most recent call last):
  File "E:\Nata\Git-nata\ReadMaster\venv\Lib\site-packages\flask\app.py", line 1511, in wsgi_app
    response = self.full_dispatch_request()
               ^^^^^^^^^^^^^^^^^^^^^^^^^^^^
  File "E:\Nata\Git-nata\ReadMaster\venv\Lib\site-packages\flask\app.py", line 919, in full_dispatch_request
    rv = self.handle_user_exception(e)
         ^^^^^^^^^^^^^^^^^^^^^^^^^^^^^
  File "E:\Nata\Git-nata\ReadMaster\venv\Lib\site-packages\flask\app.py", line 917, in full_dispatch_request
    rv = self.dispatch_request()
         ^^^^^^^^^^^^^^^^^^^^^^^
  File "E:\Nata\Git-nata\ReadMaster\venv\Lib\site-packages\flask\app.py", line 902, in dispatch_request
    return self.ensure_sync(self.view_functions[rule.endpoint])(**view_args)  # type: ignore[no-any-return]
           ^^^^^^^^^^^^^^^^^^^^^^^^^^^^^^^^^^^^^^^^^^^^^^^^^^^^^^^^^^^^^^^^^
  File "E:\Nata\Git-nata\ReadMaster\main.py", line 115, in login
    return render_template("login.html")
           ^^^^^^^^^^^^^^^^^^^^^^^^^^^^^
  File "E:\Nata\Git-nata\ReadMaster\venv\Lib\site-packages\flask\templating.py", line 150, in render_template
    return _render(app, template, context)
           ^^^^^^^^^^^^^^^^^^^^^^^^^^^^^^^
  File "E:\Nata\Git-nata\ReadMaster\venv\Lib\site-packages\flask\templating.py", line 131, in _render
    rv = template.render(context)
         ^^^^^^^^^^^^^^^^^^^^^^^^
  File "E:\Nata\Git-nata\ReadMaster\venv\Lib\site-packages\jinja2\environment.py", line 1295, in render
    self.environment.handle_exception()
  File "E:\Nata\Git-nata\ReadMaster\venv\Lib\site-packages\jinja2\environment.py", line 942, in handle_exception
    raise rewrite_traceback_stack(source=source)
  File "E:\Nata\Git-nata\ReadMaster\templates\login.html", line 25, in top-level template code
    <input type="hidden" name="_csrf_token" value="{{ csrf_token() }}">
    ^^^^^^^^^^^^^^^^^^^^^^^^^
  File "E:\Nata\Git-nata\ReadMaster\venv\Lib\site-packages\jinja2\utils.py", line 92, in from_obj
    if hasattr(obj, "jinja_pass_arg"):
       ^^^^^^^^^^^^^^^^^^^^^^^^^^^^^^
jinja2.exceptions.UndefinedError: 'csrf_token' is undefined
2025-08-10 09:18:55,951 ERROR: Exception on /login [GET] [in E:\Nata\Git-nata\ReadMaster\venv\Lib\site-packages\flask\app.py:875]
Traceback (most recent call last):
  File "E:\Nata\Git-nata\ReadMaster\venv\Lib\site-packages\flask\app.py", line 1511, in wsgi_app
    response = self.full_dispatch_request()
               ^^^^^^^^^^^^^^^^^^^^^^^^^^^^
  File "E:\Nata\Git-nata\ReadMaster\venv\Lib\site-packages\flask\app.py", line 919, in full_dispatch_request
    rv = self.handle_user_exception(e)
         ^^^^^^^^^^^^^^^^^^^^^^^^^^^^^
  File "E:\Nata\Git-nata\ReadMaster\venv\Lib\site-packages\flask\app.py", line 917, in full_dispatch_request
    rv = self.dispatch_request()
         ^^^^^^^^^^^^^^^^^^^^^^^
  File "E:\Nata\Git-nata\ReadMaster\venv\Lib\site-packages\flask\app.py", line 902, in dispatch_request
    return self.ensure_sync(self.view_functions[rule.endpoint])(**view_args)  # type: ignore[no-any-return]
           ^^^^^^^^^^^^^^^^^^^^^^^^^^^^^^^^^^^^^^^^^^^^^^^^^^^^^^^^^^^^^^^^^
  File "E:\Nata\Git-nata\ReadMaster\main.py", line 115, in login
    return render_template("login.html")
           ^^^^^^^^^^^^^^^^^^^^^^^^^^^^^
  File "E:\Nata\Git-nata\ReadMaster\venv\Lib\site-packages\flask\templating.py", line 150, in render_template
    return _render(app, template, context)
           ^^^^^^^^^^^^^^^^^^^^^^^^^^^^^^^
  File "E:\Nata\Git-nata\ReadMaster\venv\Lib\site-packages\flask\templating.py", line 131, in _render
    rv = template.render(context)
         ^^^^^^^^^^^^^^^^^^^^^^^^
  File "E:\Nata\Git-nata\ReadMaster\venv\Lib\site-packages\jinja2\environment.py", line 1295, in render
    self.environment.handle_exception()
  File "E:\Nata\Git-nata\ReadMaster\venv\Lib\site-packages\jinja2\environment.py", line 942, in handle_exception
    raise rewrite_traceback_stack(source=source)
  File "E:\Nata\Git-nata\ReadMaster\templates\login.html", line 25, in top-level template code
    <input type="hidden" name="_csrf_token" value="{{ csrf_token() }}">
    ^^^^^^^^^^^^^^^^^^^^^^^^^
  File "E:\Nata\Git-nata\ReadMaster\venv\Lib\site-packages\jinja2\utils.py", line 92, in from_obj
    if hasattr(obj, "jinja_pass_arg"):
       ^^^^^^^^^^^^^^^^^^^^^^^^^^^^^^
jinja2.exceptions.UndefinedError: 'csrf_token' is undefined
2025-08-10 09:20:00,650 ERROR: Exception on /login [POST] [in E:\Nata\Git-nata\ReadMaster\venv\Lib\site-packages\flask\app.py:875]
Traceback (most recent call last):
  File "E:\Nata\Git-nata\ReadMaster\venv\Lib\site-packages\sqlalchemy\engine\base.py", line 1961, in _exec_single_context
    self.dialect.do_execute(
  File "E:\Nata\Git-nata\ReadMaster\venv\Lib\site-packages\sqlalchemy\engine\default.py", line 944, in do_execute
    cursor.execute(statement, parameters)
sqlite3.OperationalError: no such table: users

The above exception was the direct cause of the following exception:

Traceback (most recent call last):
  File "E:\Nata\Git-nata\ReadMaster\venv\Lib\site-packages\flask\app.py", line 1511, in wsgi_app
    response = self.full_dispatch_request()
               ^^^^^^^^^^^^^^^^^^^^^^^^^^^^
  File "E:\Nata\Git-nata\ReadMaster\venv\Lib\site-packages\flask\app.py", line 919, in full_dispatch_request
    rv = self.handle_user_exception(e)
         ^^^^^^^^^^^^^^^^^^^^^^^^^^^^^
  File "E:\Nata\Git-nata\ReadMaster\venv\Lib\site-packages\flask\app.py", line 917, in full_dispatch_request
    rv = self.dispatch_request()
         ^^^^^^^^^^^^^^^^^^^^^^^
  File "E:\Nata\Git-nata\ReadMaster\venv\Lib\site-packages\flask\app.py", line 902, in dispatch_request
    return self.ensure_sync(self.view_functions[rule.endpoint])(**view_args)  # type: ignore[no-any-return]
           ^^^^^^^^^^^^^^^^^^^^^^^^^^^^^^^^^^^^^^^^^^^^^^^^^^^^^^^^^^^^^^^^^
  File "E:\Nata\Git-nata\ReadMaster\main.py", line 96, in login
    row = User.query.filter_by(login=f['usern'], passw=f['passw']).first()
          ^^^^^^^^^^^^^^^^^^^^^^^^^^^^^^^^^^^^^^^^^^^^^^^^^^^^^^^^^^^^^^^^
  File "E:\Nata\Git-nata\ReadMaster\venv\Lib\site-packages\sqlalchemy\orm\query.py", line 2759, in first
    return self.limit(1)._iter().first()  # type: ignore
           ^^^^^^^^^^^^^^^^^^^^^
  File "E:\Nata\Git-nata\ReadMaster\venv\Lib\site-packages\sqlalchemy\orm\query.py", line 2857, in _iter
    result: Union[ScalarResult[_T], Result[_T]] = self.session.execute(
                                                  ^^^^^^^^^^^^^^^^^^^^^
  File "E:\Nata\Git-nata\ReadMaster\venv\Lib\site-packages\sqlalchemy\orm\session.py", line 2365, in execute
    return self._execute_internal(
           ^^^^^^^^^^^^^^^^^^^^^^^
  File "E:\Nata\Git-nata\ReadMaster\venv\Lib\site-packages\sqlalchemy\orm\session.py", line 2251, in _execute_internal
    result: Result[Any] = compile_state_cls.orm_execute_statement(
                          ^^^^^^^^^^^^^^^^^^^^^^^^^^^^^^^^^^^^^^^^
  File "E:\Nata\Git-nata\ReadMaster\venv\Lib\site-packages\sqlalchemy\orm\context.py", line 306, in orm_execute_statement
    result = conn.execute(
             ^^^^^^^^^^^^^
  File "E:\Nata\Git-nata\ReadMaster\venv\Lib\site-packages\sqlalchemy\engine\base.py", line 1413, in execute
    return meth(
           ^^^^^
  File "E:\Nata\Git-nata\ReadMaster\venv\Lib\site-packages\sqlalchemy\sql\elements.py", line 526, in _execute_on_connection
    return connection._execute_clauseelement(
           ^^^^^^^^^^^^^^^^^^^^^^^^^^^^^^^^^^
  File "E:\Nata\Git-nata\ReadMaster\venv\Lib\site-packages\sqlalchemy\engine\base.py", line 1635, in _execute_clauseelement
    ret = self._execute_context(
          ^^^^^^^^^^^^^^^^^^^^^^
  File "E:\Nata\Git-nata\ReadMaster\venv\Lib\site-packages\sqlalchemy\engine\base.py", line 1840, in _execute_context
    return self._exec_single_context(
           ^^^^^^^^^^^^^^^^^^^^^^^^^^
  File "E:\Nata\Git-nata\ReadMaster\venv\Lib\site-packages\sqlalchemy\engine\base.py", line 1980, in _exec_single_context
    self._handle_dbapi_exception(
  File "E:\Nata\Git-nata\ReadMaster\venv\Lib\site-packages\sqlalchemy\engine\base.py", line 2349, in _handle_dbapi_exception
    raise sqlalchemy_exception.with_traceback(exc_info[2]) from e
  File "E:\Nata\Git-nata\ReadMaster\venv\Lib\site-packages\sqlalchemy\engine\base.py", line 1961, in _exec_single_context
    self.dialect.do_execute(
  File "E:\Nata\Git-nata\ReadMaster\venv\Lib\site-packages\sqlalchemy\engine\default.py", line 944, in do_execute
    cursor.execute(statement, parameters)
sqlalchemy.exc.OperationalError: (sqlite3.OperationalError) no such table: users
[SQL: SELECT users.id AS users_id, users.login AS users_login, users.passw AS users_passw, users.exten AS users_exten, users.prefix AS users_prefix, users.role AS users_role, users.ruk_id AS users_ruk_id, users.name AS users_name 
FROM users 
WHERE users.login = ? AND users.passw = ?
 LIMIT ? OFFSET ?]
[parameters: ('admin', 'admin', 1, 0)]
(Background on this error at: https://sqlalche.me/e/20/e3q8)
